[2024-06-01T16:13:00.896+0000] {task_context_logger.py:104} ERROR - Executor reports task instance <TaskInstance: etl_dag.extract scheduled__2023-03-21T00:00:00+00:00 [queued]> finished (failed) although the task says it's queued. (Info: None) Was the task killed externally?
