[2024-06-01T16:11:38.497+0000] {task_context_logger.py:104} ERROR - Executor reports task instance <TaskInstance: etl_dag.transform scheduled__2023-02-24T00:00:00+00:00 [queued]> finished (failed) although the task says it's queued. (Info: None) Was the task killed externally?
