[2024-06-03T03:45:34.488+0000] {local_task_job_runner.py:120} INFO - ::group::Pre task execution logs
[2024-06-03T03:45:34.515+0000] {taskinstance.py:2076} INFO - Dependencies all met for dep_context=non-requeueable deps ti=<TaskInstance: etl_dag.load manual__2024-06-03T03:45:14.289673+00:00 [queued]>
[2024-06-03T03:45:34.525+0000] {taskinstance.py:2076} INFO - Dependencies all met for dep_context=requeueable deps ti=<TaskInstance: etl_dag.load manual__2024-06-03T03:45:14.289673+00:00 [queued]>
[2024-06-03T03:45:34.526+0000] {taskinstance.py:2306} INFO - Starting attempt 1 of 2
[2024-06-03T03:45:34.540+0000] {taskinstance.py:2330} INFO - Executing <Task(PythonOperator): load> on 2024-06-03 03:45:14.289673+00:00
[2024-06-03T03:45:34.555+0000] {logging_mixin.py:188} WARNING - /home/***/.local/lib/python3.12/site-packages/***/task/task_runner/standard_task_runner.py:61 DeprecationWarning: This process (pid=860) is multi-threaded, use of fork() may lead to deadlocks in the child.
[2024-06-03T03:45:34.556+0000] {standard_task_runner.py:63} INFO - Started process 862 to run task
[2024-06-03T03:45:34.555+0000] {standard_task_runner.py:90} INFO - Running: ['***', 'tasks', 'run', 'etl_dag', 'load', 'manual__2024-06-03T03:45:14.289673+00:00', '--job-id', '238', '--raw', '--subdir', 'DAGS_FOLDER/etl_dag.py', '--cfg-path', '/tmp/tmpnhg0g7_t']
[2024-06-03T03:45:34.558+0000] {standard_task_runner.py:91} INFO - Job 238: Subtask load
[2024-06-03T03:45:34.579+0000] {logging_mixin.py:188} WARNING - /home/***/.local/lib/python3.12/site-packages/***/settings.py:195 DeprecationWarning: The sql_alchemy_conn option in [core] has been moved to the sql_alchemy_conn option in [database] - the old setting has been used, but please update your config.
[2024-06-03T03:45:34.617+0000] {task_command.py:426} INFO - Running <TaskInstance: etl_dag.load manual__2024-06-03T03:45:14.289673+00:00 [running]> on host aa989158b36e
[2024-06-03T03:45:34.717+0000] {taskinstance.py:2648} INFO - Exporting env vars: AIRFLOW_CTX_DAG_OWNER='***' AIRFLOW_CTX_DAG_ID='etl_dag' AIRFLOW_CTX_TASK_ID='load' AIRFLOW_CTX_EXECUTION_DATE='2024-06-03T03:45:14.289673+00:00' AIRFLOW_CTX_TRY_NUMBER='1' AIRFLOW_CTX_DAG_RUN_ID='manual__2024-06-03T03:45:14.289673+00:00'
[2024-06-03T03:45:34.719+0000] {taskinstance.py:430} INFO - ::endgroup::
[2024-06-03T03:45:34.749+0000] {logging_mixin.py:188} WARNING - /home/***/.local/lib/python3.12/site-packages/google/cloud/firestore_v1/base_collection.py:302 UserWarning: Detected filter using positional arguments. Prefer using the 'filter' keyword argument instead.
[2024-06-03T03:45:35.553+0000] {taskinstance.py:441} INFO - ::group::Post task execution logs
[2024-06-03T03:45:35.554+0000] {taskinstance.py:2905} ERROR - Task failed with exception
Traceback (most recent call last):
  File "/home/airflow/.local/lib/python3.12/site-packages/airflow/models/taskinstance.py", line 465, in _execute_task
    result = _execute_callable(context=context, **execute_callable_kwargs)
             ^^^^^^^^^^^^^^^^^^^^^^^^^^^^^^^^^^^^^^^^^^^^^^^^^^^^^^^^^^^^^
  File "/home/airflow/.local/lib/python3.12/site-packages/airflow/models/taskinstance.py", line 432, in _execute_callable
    return execute_callable(context=context, **execute_callable_kwargs)
           ^^^^^^^^^^^^^^^^^^^^^^^^^^^^^^^^^^^^^^^^^^^^^^^^^^^^^^^^^^^^
  File "/home/airflow/.local/lib/python3.12/site-packages/airflow/models/baseoperator.py", line 400, in wrapper
    return func(self, *args, **kwargs)
           ^^^^^^^^^^^^^^^^^^^^^^^^^^^
  File "/home/airflow/.local/lib/python3.12/site-packages/airflow/operators/python.py", line 235, in execute
    return_value = self.execute_callable()
                   ^^^^^^^^^^^^^^^^^^^^^^^
  File "/home/airflow/.local/lib/python3.12/site-packages/airflow/operators/python.py", line 252, in execute_callable
    return self.python_callable(*self.op_args, **self.op_kwargs)
           ^^^^^^^^^^^^^^^^^^^^^^^^^^^^^^^^^^^^^^^^^^^^^^^^^^^^^
  File "/opt/airflow/dags/etl_dag.py", line 112, in load
    pd.DataFrame(song_data).to_csv(save_path, index=False)
                 ^^^^^^^^^
UnboundLocalError: cannot access local variable 'song_data' where it is not associated with a value
[2024-06-03T03:45:35.585+0000] {taskinstance.py:1206} INFO - Marking task as UP_FOR_RETRY. dag_id=etl_dag, task_id=load, run_id=manual__2024-06-03T03:45:14.289673+00:00, execution_date=20240603T034514, start_date=20240603T034534, end_date=20240603T034535
[2024-06-03T03:45:35.610+0000] {standard_task_runner.py:110} ERROR - Failed to execute job 238 for task load (cannot access local variable 'song_data' where it is not associated with a value; 862)
[2024-06-03T03:45:35.659+0000] {local_task_job_runner.py:240} INFO - Task exited with return code 1
[2024-06-03T03:45:35.680+0000] {taskinstance.py:3498} INFO - 0 downstream tasks scheduled from follow-on schedule check
[2024-06-03T03:45:35.684+0000] {local_task_job_runner.py:222} INFO - ::endgroup::
